<?xml version="1.0" encoding="utf-8"?>
<mujoco model="drawer">
    <!--<include file="drawer_dependencies.xml"/>-->
    <compiler angle="radian" inertiafromgeom="auto" inertiagrouprange="4 5"/>
    <asset>

      <material name="drawer_col" rgba="0.3 0.3 1.0 0.5" shininess="0" specular="0"/>
      <material name="drawer_red" rgba="0.19 0.38 0.2 1" shininess="1" reflectance=".7" specular=".5"/>
      <material name="drawer_white" rgba=".75 .75 .75 1" shininess="1" reflectance=".7" specular=".5"/>
      <material name="drawer_beige" rgba=".4 .65 .4 1" shininess="1" reflectance="1" specular=".5"/>
      <mesh file="../meshes/drawer/drawer.stl" name="drawer"/>
      <mesh file="../meshes/drawer/drawercase.stl" name="drawercase"/>
      <mesh file="../meshes/drawer/drawerhandle.stl" name="drawerhandle"/>

    </asset>

    <!--
    <default>

      <default class="drawer_base">
          <joint armature="0.001" damping="2" limited="true"/>
          <geom conaffinity="0" contype="0" group="1" type="mesh"/>
          <position ctrllimited="true" ctrlrange="0 1.57"/>
          <default class="drawer_viz">
              <geom condim="4" type="mesh"/>
          </default>
          <default class="drawer_col">
              <geom conaffinity="1" condim="3" contype="1" group="4" material="drawer_col" solimp="0.99 0.99 0.01" solref="0.01 1"/>
          </default>
      </default>
    </default>
    -->

    <!-- 
    <worldbody>
      <body childclass="drawer_base">
          <body name="drawercase_link" pos="0 0 0.084">
              <geom material="drawer_beige" mesh="drawercase"/>
              <geom class="drawer_col" pos="-0.11 0 0" size="0.008 0.1 0.084" type="box" mass=".05"/>
              <geom class="drawer_col" pos="0.11 0 0" size="0.008 0.1 0.084" type="box" mass=".05"/>
              <geom class="drawer_col" pos="0 0.092 -0.008" size="0.102 0.008 0.076" type="box" mass=".05"/>
              <geom class="drawer_col" pos="0 -0.008 -0.07" size="0.102 0.092 0.014" type="box" mass=".05"/>
              <geom class="drawer_col" pos="0 0 0.076" size="0.102 0.1 0.008" type="box" mass=".05"/>
              <body name="drawer_link" pos="0 -0.01 0.006">
                  <joint type="slide" range="-0.16 0" axis="0 1 0" name="goal_slidey" pos="0 0 0" damping="2"/>
                  <geom material="drawer_beige" mesh="drawer"/>
                  <geom material="drawer_white" mesh="drawerhandle" pos="0 -0.114 0" name="objGeom"/>
                  <geom class="drawer_col" pos="0 -0.082 0.008" size="0.1 0.008 0.052" type="box" mass=".04"/>
                  <geom class="drawer_col" pos="0 0.082 0.008" size="0.1 0.008 0.052" type="box" mass=".04"/>
                  <geom class="drawer_col" pos="-0.092 0 0.008" size="0.008 0.074 0.052" type="box" mass=".04"/>
                  <geom class="drawer_col" pos="0.092 0 0.008" size="0.008 0.074 0.052" type="box" mass=".04"/>
                  <geom class="drawer_col" pos="0 0 -0.052" size="0.1 0.09 0.008" type="box" mass=".04"/>
                  <geom class="drawer_col" euler="1.571 0 0" pos="-0.05 -0.12 0.0" size="0.009 0.03" type="capsule" mass=".06"/>
                  <geom class="drawer_col" euler="0 1.57 0" pos="0 -0.15 0" size="0.009 0.05" type="capsule" mass=".06"/>
                  <geom class="drawer_col" euler="1.57 0 0" pos="0.05 -0.12 0" size="0.009 0.03" type="capsule" mass=".06"/>
              </body>
          </body>
      </body>
    </worldbody>
    -->

    <worldbody>
      <body>
          <!--<body name="drawercase_link" pos="0 0 0.084">-->
          <body name="object" pos="0 0 0.084">
              <geom material="drawer_beige" mesh="drawercase" group="1"/>
              <geom conaffinity="1" condim="3" contype="1" group="0" material="drawer_col" solimp="0.99 0.99 0.01" solref="0.01 1" pos="-0.11 0 0" size="0.008 0.1 0.084" type="box" mass=".05"/>
              <geom conaffinity="1" condim="3" contype="1" group="0" material="drawer_col" solimp="0.99 0.99 0.01" solref="0.01 1" pos="0.11 0 0" size="0.008 0.1 0.084" type="box" mass=".05"/>
              <geom conaffinity="1" condim="3" contype="1" group="0" material="drawer_col" solimp="0.99 0.99 0.01" solref="0.01 1" pos="0 0.092 -0.008" size="0.102 0.008 0.076" type="box" mass=".05"/>
              <geom conaffinity="1" condim="3" contype="1" group="0" material="drawer_col" solimp="0.99 0.99 0.01" solref="0.01 1" pos="0 -0.008 -0.07" size="0.102 0.092 0.014" type="box" mass=".05"/>
              <geom conaffinity="1" condim="3" contype="1" group="0" material="drawer_col" solimp="0.99 0.99 0.01" solref="0.01 1" pos="0 0 0.076" size="0.102 0.1 0.008" type="box" mass=".05"/>
              <body name="drawer_link" pos="0 -0.01 0.006">
                  <joint armature="0.001" limited="true" type="slide" range="-0.16 0" axis="0 1 0" name="goal_slidey" pos="0 0 0" damping="2"/>
                  <geom material="drawer_beige" mesh="drawer" group="1"/>
                  <geom material="drawer_white" mesh="drawerhandle" pos="0 -0.114 0" name="objGeom" group="1"/>
                  <geom conaffinity="1" condim="3" contype="1" group="0" material="drawer_col" solimp="0.99 0.99 0.01" solref="0.01 1" pos="0 -0.082 0.008" size="0.1 0.008 0.052" type="box" mass=".04"/>
                  <geom conaffinity="1" condim="3" contype="1" group="0" material="drawer_col" solimp="0.99 0.99 0.01" solref="0.01 1" pos="0 0.082 0.008" size="0.1 0.008 0.052" type="box" mass=".04"/>
                  <geom conaffinity="1" condim="3" contype="1" group="0" material="drawer_col" solimp="0.99 0.99 0.01" solref="0.01 1" pos="-0.092 0 0.008" size="0.008 0.074 0.052" type="box" mass=".04"/>
                  <geom conaffinity="1" condim="3" contype="1" group="0" material="drawer_col" solimp="0.99 0.99 0.01" solref="0.01 1" pos="0.092 0 0.008" size="0.008 0.074 0.052" type="box" mass=".04"/>
                  <geom conaffinity="1" condim="3" contype="1" group="0" material="drawer_col" solimp="0.99 0.99 0.01" solref="0.01 1" pos="0 0 -0.052" size="0.1 0.09 0.008" type="box" mass=".04"/>
                  <geom conaffinity="1" condim="3" contype="1" group="0" material="drawer_col" solimp="0.99 0.99 0.01" solref="0.01 1" euler="1.571 0 0" pos="-0.05 -0.12 0.0" size="0.009 0.03" type="capsule" mass=".06"/>
                  <geom conaffinity="1" condim="3" contype="1" group="0" material="drawer_col" solimp="0.99 0.99 0.01" solref="0.01 1" euler="0 1.57 0" pos="0 -0.15 0" size="0.009 0.05" type="capsule" mass=".06"/>
                  <geom conaffinity="1" condim="3" contype="1" group="0" material="drawer_col" solimp="0.99 0.99 0.01" solref="0.01 1" euler="1.57 0 0" pos="0.05 -0.12 0" size="0.009 0.03" type="capsule" mass=".06"/>
              </body>
          </body>
      <site rgba="0 0 0 0" size="0.2" pos="0 0 0.5" name="bottom_site"/>
      <site rgba="0 0 0 0" size="0.2" pos="0 0 -0.5" name="top_site"/>
      <site rgba="0 0 0 0" size="0.2" pos="0.5 0 0" name="horizontal_radius_site"/>
      </body>
    </worldbody>

</mujoco>
